Workbook
Name Client_Margin: _xlfn.LAMBDA(_xlpm.ClientID,_xlfn._xlws.FILTER(Fund[Margin],Fund[Client Id]=_xlpm.ClientID))
Name Client_Margin: _xlfn.LAMBDA(_xlpm.ClientID,_xlfn._xlws.FILTER(Fund[Margin],Fund[Client Id]=_xlpm.ClientID))

Sheet Margin
B2: Strategy | C2: SENSEX | D2: BANKNIFTY | E2: NIFTY | R2: Client Id | S2: Client Name | T2: Pledge Value | U2: Margin | V2: Column1
B3: TTP | C3: 33 | E3: 33 | H3: Index | I3: Strategy | J3: Expectancy | K3: N.Expiry_W.O.H | L3: N.Expiry_W.H | M3: Expiry_W.O.H | N3: Expiry_W.H | O3: Strategy allotment % without hedge | P3: Strategy allotment % with hedge | R3: YJJ03 | S3: Rasalika Investment | T3: 30000000 | U3: 24000000 | V3: Z1IT20
B4: TTA | C4: 33 | E4: 0 | H4: NIFTY | I4: TTP | K4: {=INDEX(LOT[#All],MATCH(Margin[[#This Row],[Strategy]],LOT[[#All],[Strategy]],0),MATCH(Margin[[#This Row],[Index]],LOT[#Headers],0))*_xlfn._xlws.FILTER(MR_2[W.O.H],(MR_2[Index]=Margin[[#This Row],[Index]])*(MR_2[Day Type]="N.Expiry"))} -> 8613000 | L4: {=INDEX(LOT[#All],MATCH(Margin[[#This Row],[Strategy]],LOT[[#All],[Strategy]],0),MATCH(Margin[[#This Row],[Index]],LOT[#Headers],0))*_xlfn._xlws.FILTER(MR_2[W.H],(MR_2[Index]=Margin[[#This Row],[Index]])*(MR_2[Day Type]="N.Expiry"))} -> 5280000 | M4: {=INDEX(LOT[#All],MATCH(Margin[[#This Row],[Strategy]],LOT[[#All],[Strategy]],0),MATCH(Margin[[#This Row],[Index]],LOT[#Headers],0))*_xlfn._xlws.FILTER(MR_2[W.O.H],(MR_2[Index]=Margin[[#This Row],[Index]])*(MR_2[Day Type]="Expiry"))} -> 11220000 | N4: {=INDEX(LOT[#All],MATCH(Margin[[#This Row],[Strategy]],LOT[[#All],[Strategy]],0),MATCH(Margin[[#This Row],[Index]],LOT[#Headers],0))*_xlfn._xlws.FILTER(MR_2[W.H],(MR_2[Index]=Margin[[#This Row],[Index]])*(MR_2[Day Type]="Expiry"))} -> 7920000 | R4: YJJ02 | S4: USL Investments | T4: 30000000 | U4: 28000000
B5: SH | C5: 11 | E5: 21 | H5: NIFTY | I5: TTA | K5: {=INDEX(LOT[#All],MATCH(Margin[[#This Row],[Strategy]],LOT[[#All],[Strategy]],0),MATCH(Margin[[#This Row],[Index]],LOT[#Headers],0))*_xlfn._xlws.FILTER(MR_2[W.O.H],(MR_2[Index]=Margin[[#This Row],[Index]])*(MR_2[Day Type]="N.Expiry"))} -> 0 | L5: {=INDEX(LOT[#All],MATCH(Margin[[#This Row],[Strategy]],LOT[[#All],[Strategy]],0),MATCH(Margin[[#This Row],[Index]],LOT[#Headers],0))*_xlfn._xlws.FILTER(MR_2[W.H],(MR_2[Index]=Margin[[#This Row],[Index]])*(MR_2[Day Type]="N.Expiry"))} -> 0 | M5: {=INDEX(LOT[#All],MATCH(Margin[[#This Row],[Strategy]],LOT[[#All],[Strategy]],0),MATCH(Margin[[#This Row],[Index]],LOT[#Headers],0))*_xlfn._xlws.FILTER(MR_2[W.O.H],(MR_2[Index]=Margin[[#This Row],[Index]])*(MR_2[Day Type]="Expiry"))} -> 0 | N5: {=INDEX(LOT[#All],MATCH(Margin[[#This Row],[Strategy]],LOT[[#All],[Strategy]],0),MATCH(Margin[[#This Row],[Index]],LOT[#Headers],0))*_xlfn._xlws.FILTER(MR_2[W.H],(MR_2[Index]=Margin[[#This Row],[Index]])*(MR_2[Day Type]="Expiry"))} -> 0 | R5: YJJ01 | S5: Ashok Kasat | T5: 30000000 | U5: 29000000 | V5: Z1IT23
B6: DYNAMIC SL | C6: 6 | D6: 6 | E6: 10 | H6: SENSEX | I6: TTP | K6: {=INDEX(LOT[#All],MATCH(Margin[[#This Row],[Strategy]],LOT[[#All],[Strategy]],0),MATCH(Margin[[#This Row],[Index]],LOT[#Headers],0))*_xlfn._xlws.FILTER(MR_2[W.O.H],(MR_2[Index]=Margin[[#This Row],[Index]])*(MR_2[Day Type]="N.Expiry"))} -> 7359000 | L6: {=INDEX(LOT[#All],MATCH(Margin[[#This Row],[Strategy]],LOT[[#All],[Strategy]],0),MATCH(Margin[[#This Row],[Index]],LOT[#Headers],0))*_xlfn._xlws.FILTER(MR_2[W.H],(MR_2[Index]=Margin[[#This Row],[Index]])*(MR_2[Day Type]="N.Expiry"))} -> 3828000 | M6: {=INDEX(LOT[#All],MATCH(Margin[[#This Row],[Strategy]],LOT[[#All],[Strategy]],0),MATCH(Margin[[#This Row],[Index]],LOT[#Headers],0))*_xlfn._xlws.FILTER(MR_2[W.O.H],(MR_2[Index]=Margin[[#This Row],[Index]])*(MR_2[Day Type]="Expiry"))} -> 9900000 | N6: {=INDEX(LOT[#All],MATCH(Margin[[#This Row],[Strategy]],LOT[[#All],[Strategy]],0),MATCH(Margin[[#This Row],[Index]],LOT[#Headers],0))*_xlfn._xlws.FILTER(MR_2[W.H],(MR_2[Index]=Margin[[#This Row],[Index]])*(MR_2[Day Type]="Expiry"))} -> 6105000 | R6: SAT2484 | S6: NIRANJAN RATHI | T6: 53860000 | U6: 40000000
B7: ITM SH | C7: 0 | E7: 11 | H7: SENSEX | I7: TTA | K7: {=INDEX(LOT[#All],MATCH(Margin[[#This Row],[Strategy]],LOT[[#All],[Strategy]],0),MATCH(Margin[[#This Row],[Index]],LOT[#Headers],0))*_xlfn._xlws.FILTER(MR_2[W.O.H],(MR_2[Index]=Margin[[#This Row],[Index]])*(MR_2[Day Type]="N.Expiry"))} -> 7359000 | L7: {=INDEX(LOT[#All],MATCH(Margin[[#This Row],[Strategy]],LOT[[#All],[Strategy]],0),MATCH(Margin[[#This Row],[Index]],LOT[#Headers],0))*_xlfn._xlws.FILTER(MR_2[W.H],(MR_2[Index]=Margin[[#This Row],[Index]])*(MR_2[Day Type]="N.Expiry"))} -> 3828000 | M7: {=INDEX(LOT[#All],MATCH(Margin[[#This Row],[Strategy]],LOT[[#All],[Strategy]],0),MATCH(Margin[[#This Row],[Index]],LOT[#Headers],0))*_xlfn._xlws.FILTER(MR_2[W.O.H],(MR_2[Index]=Margin[[#This Row],[Index]])*(MR_2[Day Type]="Expiry"))} -> 9900000 | N7: {=INDEX(LOT[#All],MATCH(Margin[[#This Row],[Strategy]],LOT[[#All],[Strategy]],0),MATCH(Margin[[#This Row],[Index]],LOT[#Headers],0))*_xlfn._xlws.FILTER(MR_2[W.H],(MR_2[Index]=Margin[[#This Row],[Index]])*(MR_2[Day Type]="Expiry"))} -> 6105000 | R7: OWN | S7: Prarambh | T7: 75000000 | U7: 75000000
B8: ITM CE | C8: 0 | E8: 1 | H8: NIFTY | I8: SH | K8: {=INDEX(LOT[#All],MATCH(Margin[[#This Row],[Strategy]],LOT[[#All],[Strategy]],0),MATCH(Margin[[#This Row],[Index]],LOT[#Headers],0))*_xlfn._xlws.FILTER(MR_2[W.O.H],(MR_2[Index]=Margin[[#This Row],[Index]])*(MR_2[Day Type]="N.Expiry"))} -> 5481000 | L8: {=INDEX(LOT[#All],MATCH(Margin[[#This Row],[Strategy]],LOT[[#All],[Strategy]],0),MATCH(Margin[[#This Row],[Index]],LOT[#Headers],0))*_xlfn._xlws.FILTER(MR_2[W.H],(MR_2[Index]=Margin[[#This Row],[Index]])*(MR_2[Day Type]="N.Expiry"))} -> 3360000 | M8: {=INDEX(LOT[#All],MATCH(Margin[[#This Row],[Strategy]],LOT[[#All],[Strategy]],0),MATCH(Margin[[#This Row],[Index]],LOT[#Headers],0))*_xlfn._xlws.FILTER(MR_2[W.O.H],(MR_2[Index]=Margin[[#This Row],[Index]])*(MR_2[Day Type]="Expiry"))} -> 7140000 | N8: {=INDEX(LOT[#All],MATCH(Margin[[#This Row],[Strategy]],LOT[[#All],[Strategy]],0),MATCH(Margin[[#This Row],[Index]],LOT[#Headers],0))*_xlfn._xlws.FILTER(MR_2[W.H],(MR_2[Index]=Margin[[#This Row],[Index]])*(MR_2[Day Type]="Expiry"))} -> 5040000 | R8: MOSTI23482 | S8: Sarla Lakhotia | T8: 63000000 | U8: 46000000 | V8: Z1IT21
B9: TO | C9: 3 | E9: 4 | H9: NIFTY | I9: ITM SH | K9: {=INDEX(LOT[#All],MATCH(Margin[[#This Row],[Strategy]],LOT[[#All],[Strategy]],0),MATCH(Margin[[#This Row],[Index]],LOT[#Headers],0))*_xlfn._xlws.FILTER(MR_2[W.O.H],(MR_2[Index]=Margin[[#This Row],[Index]])*(MR_2[Day Type]="N.Expiry"))} -> 2871000 | L9: {=INDEX(LOT[#All],MATCH(Margin[[#This Row],[Strategy]],LOT[[#All],[Strategy]],0),MATCH(Margin[[#This Row],[Index]],LOT[#Headers],0))*_xlfn._xlws.FILTER(MR_2[W.H],(MR_2[Index]=Margin[[#This Row],[Index]])*(MR_2[Day Type]="N.Expiry"))} -> 1760000 | M9: {=INDEX(LOT[#All],MATCH(Margin[[#This Row],[Strategy]],LOT[[#All],[Strategy]],0),MATCH(Margin[[#This Row],[Index]],LOT[#Headers],0))*_xlfn._xlws.FILTER(MR_2[W.O.H],(MR_2[Index]=Margin[[#This Row],[Index]])*(MR_2[Day Type]="Expiry"))} -> 3740000 | N9: {=INDEX(LOT[#All],MATCH(Margin[[#This Row],[Strategy]],LOT[[#All],[Strategy]],0),MATCH(Margin[[#This Row],[Index]],LOT[#Headers],0))*_xlfn._xlws.FILTER(MR_2[W.H],(MR_2[Index]=Margin[[#This Row],[Index]])*(MR_2[Day Type]="Expiry"))} -> 2640000 | P9: 0.1 | R9: MOSTI23461 | S9: Pankaj Pilani | T9: 24000000 | U9: 24000000 | V9: Z1IT24
B10: MJ | C10: 0 | E10: 1 | H10: SENSEX | I10: 2T3 TO | K10: {=INDEX(LOT[#All],MATCH(Margin[[#This Row],[Strategy]],LOT[[#All],[Strategy]],0),MATCH(Margin[[#This Row],[Index]],LOT[#Headers],0))*_xlfn._xlws.FILTER(MR_2[W.O.H],(MR_2[Index]=Margin[[#This Row],[Index]])*(MR_2[Day Type]="N.Expiry"))} -> 669000 | L10: {=INDEX(LOT[#All],MATCH(Margin[[#This Row],[Strategy]],LOT[[#All],[Strategy]],0),MATCH(Margin[[#This Row],[Index]],LOT[#Headers],0))*_xlfn._xlws.FILTER(MR_2[W.H],(MR_2[Index]=Margin[[#This Row],[Index]])*(MR_2[Day Type]="N.Expiry"))} -> 348000 | M10: {=INDEX(LOT[#All],MATCH(Margin[[#This Row],[Strategy]],LOT[[#All],[Strategy]],0),MATCH(Margin[[#This Row],[Index]],LOT[#Headers],0))*_xlfn._xlws.FILTER(MR_2[W.O.H],(MR_2[Index]=Margin[[#This Row],[Index]])*(MR_2[Day Type]="Expiry"))} -> 900000 | N10: {=INDEX(LOT[#All],MATCH(Margin[[#This Row],[Strategy]],LOT[[#All],[Strategy]],0),MATCH(Margin[[#This Row],[Index]],LOT[#Headers],0))*_xlfn._xlws.FILTER(MR_2[W.H],(MR_2[Index]=Margin[[#This Row],[Index]])*(MR_2[Day Type]="Expiry"))} -> 555000 | P10: 0.1 | R10: MOSTI23395 | S10: Anu Kalani | T10: 18000000 | U10: 18000000 | V10: Z1IT20
B11: OI | C11: 1 | E11: 1 | H11: NIFTY | I11: TO | K11: {=INDEX(LOT[#All],MATCH(Margin[[#This Row],[Strategy]],LOT[[#All],[Strategy]],0),MATCH(Margin[[#This Row],[Index]],LOT[#Headers],0))*_xlfn._xlws.FILTER(MR_2[W.O.H],(MR_2[Index]=Margin[[#This Row],[Index]])*(MR_2[Day Type]="N.Expiry"))} -> 1044000 | L11: {=INDEX(LOT[#All],MATCH(Margin[[#This Row],[Strategy]],LOT[[#All],[Strategy]],0),MATCH(Margin[[#This Row],[Index]],LOT[#Headers],0))*_xlfn._xlws.FILTER(MR_2[W.H],(MR_2[Index]=Margin[[#This Row],[Index]])*(MR_2[Day Type]="N.Expiry"))} -> 640000 | M11: {=INDEX(LOT[#All],MATCH(Margin[[#This Row],[Strategy]],LOT[[#All],[Strategy]],0),MATCH(Margin[[#This Row],[Index]],LOT[#Headers],0))*_xlfn._xlws.FILTER(MR_2[W.O.H],(MR_2[Index]=Margin[[#This Row],[Index]])*(MR_2[Day Type]="Expiry"))} -> 1360000 | N11: {=INDEX(LOT[#All],MATCH(Margin[[#This Row],[Strategy]],LOT[[#All],[Strategy]],0),MATCH(Margin[[#This Row],[Index]],LOT[#Headers],0))*_xlfn._xlws.FILTER(MR_2[W.H],(MR_2[Index]=Margin[[#This Row],[Index]])*(MR_2[Day Type]="Expiry"))} -> 960000 | P11: 0.45 | R11: MOSTI23372 | S11: ASHOK KASAT | T11: 26800000 | U11: 26500000
B12: NFBT RB | C12: 1 | E12: 1 | H12: SENSEX | I12: TO | K12: {=INDEX(LOT[#All],MATCH(Margin[[#This Row],[Strategy]],LOT[[#All],[Strategy]],0),MATCH(Margin[[#This Row],[Index]],LOT[#Headers],0))*_xlfn._xlws.FILTER(MR_2[W.O.H],(MR_2[Index]=Margin[[#This Row],[Index]])*(MR_2[Day Type]="N.Expiry"))} -> 669000 | L12: {=INDEX(LOT[#All],MATCH(Margin[[#This Row],[Strategy]],LOT[[#All],[Strategy]],0),MATCH(Margin[[#This Row],[Index]],LOT[#Headers],0))*_xlfn._xlws.FILTER(MR_2[W.H],(MR_2[Index]=Margin[[#This Row],[Index]])*(MR_2[Day Type]="N.Expiry"))} -> 348000 | M12: {=INDEX(LOT[#All],MATCH(Margin[[#This Row],[Strategy]],LOT[[#All],[Strategy]],0),MATCH(Margin[[#This Row],[Index]],LOT[#Headers],0))*_xlfn._xlws.FILTER(MR_2[W.O.H],(MR_2[Index]=Margin[[#This Row],[Index]])*(MR_2[Day Type]="Expiry"))} -> 900000 | N12: {=INDEX(LOT[#All],MATCH(Margin[[#This Row],[Strategy]],LOT[[#All],[Strategy]],0),MATCH(Margin[[#This Row],[Index]],LOT[#Headers],0))*_xlfn._xlws.FILTER(MR_2[W.H],(MR_2[Index]=Margin[[#This Row],[Index]])*(MR_2[Day Type]="Expiry"))} -> 555000 | P12: 0.4 | R12: MOSTI23247 | S12: VATSAL RATHI | T12: 15300000 | U12: 16000000
B13: NFBT TR | C13: 1 | E13: 1 | H13: NIFTY | I13: DYNAMIC SL | K13: {=INDEX(LOT[#All],MATCH(Margin[[#This Row],[Strategy]],LOT[[#All],[Strategy]],0),MATCH(Margin[[#This Row],[Index]],LOT[#Headers],0))*_xlfn._xlws.FILTER(MR_2[W.O.H],(MR_2[Index]=Margin[[#This Row],[Index]])*(MR_2[Day Type]="N.Expiry"))} -> 2610000 | L13: {=INDEX(LOT[#All],MATCH(Margin[[#This Row],[Strategy]],LOT[[#All],[Strategy]],0),MATCH(Margin[[#This Row],[Index]],LOT[#Headers],0))*_xlfn._xlws.FILTER(MR_2[W.H],(MR_2[Index]=Margin[[#This Row],[Index]])*(MR_2[Day Type]="N.Expiry"))} -> 1600000 | M13: {=INDEX(LOT[#All],MATCH(Margin[[#This Row],[Strategy]],LOT[[#All],[Strategy]],0),MATCH(Margin[[#This Row],[Index]],LOT[#Headers],0))*_xlfn._xlws.FILTER(MR_2[W.O.H],(MR_2[Index]=Margin[[#This Row],[Index]])*(MR_2[Day Type]="Expiry"))} -> 3400000 | N13: {=INDEX(LOT[#All],MATCH(Margin[[#This Row],[Strategy]],LOT[[#All],[Strategy]],0),MATCH(Margin[[#This Row],[Index]],LOT[#Headers],0))*_xlfn._xlws.FILTER(MR_2[W.H],(MR_2[Index]=Margin[[#This Row],[Index]])*(MR_2[Day Type]="Expiry"))} -> 2400000 | P13: 0.1 | R13: MOSTI23035 | S13: Pushpa Jajoo | U13: 70000000
B14: NFBT BTF | C14: 1 | E14: 1 | H14: BANKNIFTY | I14: DYNAMIC SL | K14: {=INDEX(LOT[#All],MATCH(Margin[[#This Row],[Strategy]],LOT[[#All],[Strategy]],0),MATCH(Margin[[#This Row],[Index]],LOT[#Headers],0))*_xlfn._xlws.FILTER(MR_2[W.O.H],(MR_2[Index]=Margin[[#This Row],[Index]])*(MR_2[Day Type]="N.Expiry"))} -> 1872000 | L14: {=INDEX(LOT[#All],MATCH(Margin[[#This Row],[Strategy]],LOT[[#All],[Strategy]],0),MATCH(Margin[[#This Row],[Index]],LOT[#Headers],0))*_xlfn._xlws.FILTER(MR_2[W.H],(MR_2[Index]=Margin[[#This Row],[Index]])*(MR_2[Day Type]="N.Expiry"))} -> 1056000 | M14: {=INDEX(LOT[#All],MATCH(Margin[[#This Row],[Strategy]],LOT[[#All],[Strategy]],0),MATCH(Margin[[#This Row],[Index]],LOT[#Headers],0))*_xlfn._xlws.FILTER(MR_2[W.O.H],(MR_2[Index]=Margin[[#This Row],[Index]])*(MR_2[Day Type]="Expiry"))} -> 2400000 | N14: {=INDEX(LOT[#All],MATCH(Margin[[#This Row],[Strategy]],LOT[[#All],[Strategy]],0),MATCH(Margin[[#This Row],[Index]],LOT[#Headers],0))*_xlfn._xlws.FILTER(MR_2[W.H],(MR_2[Index]=Margin[[#This Row],[Index]])*(MR_2[Day Type]="Expiry"))} -> 1500000 | O14: 0.1 | R14: MOSTI22967 | S14: Snehlata Jajoo | U14: 18500000 | X14: sti
B15: Rolling Std | C15: 1 | E15: 1 | H15: SENSEX | I15: DYNAMIC SL | K15: {=INDEX(LOT[#All],MATCH(Margin[[#This Row],[Strategy]],LOT[[#All],[Strategy]],0),MATCH(Margin[[#This Row],[Index]],LOT[#Headers],0))*_xlfn._xlws.FILTER(MR_2[W.O.H],(MR_2[Index]=Margin[[#This Row],[Index]])*(MR_2[Day Type]="N.Expiry"))} -> 1338000 | L15: {=INDEX(LOT[#All],MATCH(Margin[[#This Row],[Strategy]],LOT[[#All],[Strategy]],0),MATCH(Margin[[#This Row],[Index]],LOT[#Headers],0))*_xlfn._xlws.FILTER(MR_2[W.H],(MR_2[Index]=Margin[[#This Row],[Index]])*(MR_2[Day Type]="N.Expiry"))} -> 696000 | M15: {=INDEX(LOT[#All],MATCH(Margin[[#This Row],[Strategy]],LOT[[#All],[Strategy]],0),MATCH(Margin[[#This Row],[Index]],LOT[#Headers],0))*_xlfn._xlws.FILTER(MR_2[W.O.H],(MR_2[Index]=Margin[[#This Row],[Index]])*(MR_2[Day Type]="Expiry"))} -> 1800000 | N15: {=INDEX(LOT[#All],MATCH(Margin[[#This Row],[Strategy]],LOT[[#All],[Strategy]],0),MATCH(Margin[[#This Row],[Index]],LOT[#Headers],0))*_xlfn._xlws.FILTER(MR_2[W.H],(MR_2[Index]=Margin[[#This Row],[Index]])*(MR_2[Day Type]="Expiry"))} -> 1110000 | P15: 0.1 | R15: MOSTI22962 | S15: Om Jajoo | U15: 13000000
B16: Rolling Stg | C16: 1 | E16: 1 | H16: NIFTY | I16: NFBT RB | K16: 350000 | L16: 350000 | M16: 350000 | N16: 350000 | R16: MOSTI22960 | S16: Anil Jajoo | T16: 55000000 | U16: 20000000 | V16: Z1IT21
B17: Calender | C17: 1 | E17: 1 | H17: NIFTY | I17: NFBT TR | K17: 350000 | L17: 350000 | M17: 350000 | N17: 350000 | R17: ITC2472 | S17: Sighals Investments | T17: 69000000 | U17: 68000000 | V17: Z1IT23
B18: Monthly Avg | C18: 1 | E18: 1 | H18: NIFTY | I18: NFBT BTF | K18: 350000 | L18: 350000 | M18: 350000 | N18: 350000 | R18: ITC2363 | S18: Om Jajoo | T18: 19000000 | U18: 17000000 | V18: Z1IT24
B19: Weekly Avg | C19: 1 | E19: 1 | H19: NIFTY | I19: Rolling Std | K19: {=IF(Margin[[#This Row],[Index]]="NIFTY",_xlfn._xlws.FILTER(LOT[NIFTY],(LOT[Strategy]=Margin[[#This Row],[Strategy]]))*$D$30,IF(Margin[[#This Row],[Index]]="SENSEX",_xlfn._xlws.FILTER(LOT[SENSEX],(LOT[Strategy]=Margin[[#This Row],[Strategy]]))*$D$41,_xlfn._xlws.FILTER(LOT[BANKNIFTY],(LOT[Strategy]=Margin[[#This Row],[Strategy]]))*$D$52))} -> 340000 | L19: {=IF(Margin[[#This Row],[Index]]="NIFTY",_xlfn._xlws.FILTER(LOT[NIFTY],(LOT[Strategy]=Margin[[#This Row],[Strategy]]))*$D$31,IF(Margin[[#This Row],[Index]]="SENSEX",_xlfn._xlws.FILTER(LOT[SENSEX],(LOT[Strategy]=Margin[[#This Row],[Strategy]]))*$D$42,_xlfn._xlws.FILTER(LOT[BANKNIFTY],(LOT[Strategy]=Margin[[#This Row],[Strategy]]))*$D$53))} -> 235000 | R19: ITC2348 | S19: Kabra Commercial Ltd | T19: 13000000 | U19: 13000000 | V19: Z1IT24
B20: 2T3 TO | C20: 3 | H20: NIFTY | I20: Rolling Stg | K20: {=IF(Margin[[#This Row],[Index]]="NIFTY",_xlfn._xlws.FILTER(LOT[NIFTY],(LOT[Strategy]=Margin[[#This Row],[Strategy]]))*$D$30,IF(Margin[[#This Row],[Index]]="SENSEX",_xlfn._xlws.FILTER(LOT[SENSEX],(LOT[Strategy]=Margin[[#This Row],[Strategy]]))*$D$41,_xlfn._xlws.FILTER(LOT[BANKNIFTY],(LOT[Strategy]=Margin[[#This Row],[Strategy]]))*$D$52))} -> 340000 | L20: {=IF(Margin[[#This Row],[Index]]="NIFTY",_xlfn._xlws.FILTER(LOT[NIFTY],(LOT[Strategy]=Margin[[#This Row],[Strategy]]))*$D$31,IF(Margin[[#This Row],[Index]]="SENSEX",_xlfn._xlws.FILTER(LOT[SENSEX],(LOT[Strategy]=Margin[[#This Row],[Strategy]]))*$D$42,_xlfn._xlws.FILTER(LOT[BANKNIFTY],(LOT[Strategy]=Margin[[#This Row],[Strategy]]))*$D$53))} -> 235000 | R20: ITC2332 | S20: SANKALP SONI | U20: 14500000
H21: NIFTY | I21: Calender | K21: 2500000 | R21: ITC2295 | S21: Sakshi Maheshwari | T21: 22000000 | U21: 18000000 | V21: Z1IT20
H22: NIFTY | I22: Monthly Avg | R22: ITC2274 | S22: Dhanshree fashion | T22: 14000000 | U22: 15000000 | V22: Z1IT24
B23: Nifty Index | C23: 25000 | H23: NIFTY | I23: Weekly Avg | R23: ITC2142 | S23: Raghvendra Singh | T23: 40000000 | U23: 51000000 | V23: Z1IT21
B24: Lot | C24: 75 | H24: NIFTY | I24: MJ | R24: ITC2095 | S24: Ratan Lakhotia | T24: 30000000 | U24: 28000000 | V24: Z1IT23
B25: Exposure | C25: =C23*C24 -> 1875000 | H25: NIFTY | I25: OI | K25: 261000 | L25: 160000 | M25: 261000 | N25: 160000 | P25: 0.05 | R25: ITC1959 | S25: Snehlata Jajoo | T25: 23000000 | U25: 20000000 | V25: Z1IT20
B26: SPAN % | C26: 0.095 | H26: SENSEX | I26: OI | K26: {=IF(Margin[[#This Row],[Index]]="NIFTY",_xlfn._xlws.FILTER(LOT[NIFTY],(LOT[Strategy]=Margin[[#This Row],[Strategy]]))*$D$30,IF(Margin[[#This Row],[Index]]="SENSEX",_xlfn._xlws.FILTER(LOT[SENSEX],(LOT[Strategy]=Margin[[#This Row],[Strategy]]))*$D$41,_xlfn._xlws.FILTER(LOT[BANKNIFTY],(LOT[Strategy]=Margin[[#This Row],[Strategy]]))*$D$52))} -> 300000 | L26: {=IF(Margin[[#This Row],[Index]]="NIFTY",_xlfn._xlws.FILTER(LOT[NIFTY],(LOT[Strategy]=Margin[[#This Row],[Strategy]]))*$D$31,IF(Margin[[#This Row],[Index]]="SENSEX",_xlfn._xlws.FILTER(LOT[SENSEX],(LOT[Strategy]=Margin[[#This Row],[Strategy]]))*$D$42,_xlfn._xlws.FILTER(LOT[BANKNIFTY],(LOT[Strategy]=Margin[[#This Row],[Strategy]]))*$D$53))} -> 185000 | R26: ITC1695 | S26: Pushpa Jajoo | T26: 63000000 | U26: 57500000 | V26: Z1IT21
B27: Margin Benefit % | C27: 0.055 | H27: NIFTY | I27: ITM CE
B28: Exposure % | C28: 0.02
B29: ELM % | C29: 0.02
B30: 1 Lot Margin without hedge | C30: =(C23*C24)*C26+(C23*C24)*C28+(C23*C24)*C29 -> 253125 | D30: 340000
B31: 1 Lot Margin With Hedge | C31: =(C23*C24)*C26+(C23*C24)*C28+(C23*C24)*C29-(C23*C24)*C27 -> 150000 | D31: 235000
B32: Leverage | C32: =C25/C30 -> 7.4074074 | H32: Index | I32: Day Type | J32: W.H | K32: W.O.H
H33: SENSEX | I33: Expiry | J33: 185000 | K33: 300000
B34: Sensex Index | C34: 82500 | H34: SENSEX | I34: N.Expiry | J34: 116000 | K34: 223000
B35: Lot | C35: 20 | H35: NIFTY | I35: Expiry | J35: 240000 | K35: 340000
B36: Exposure | C36: =C34*C35 -> 1650000 | H36: NIFTY | I36: N.Expiry | J36: 160000 | K36: 261000
B37: SPAN % | C37: 0.095 | H37: BANKNIFTY | I37: Expiry | J37: 250000 | K37: 400000
B38: Margin Benefit % | C38: 0.055 | H38: BANKNIFTY | I38: N.Expiry | J38: 176000 | K38: 312000
B39: Exposure % | C39: 0.02
B40: ELM % | C40: 0.02
B41: 1 Lot Margin without hedge | C41: =(C34*C35)*C37+(C34*C35)*C39+(C34*C35)*C40 -> 222750 | D41: 300000
...

Sheet Mon
F1: N.Expiry | G1: Expiry | H1: N.Expiry | I1: N.Expiry | J1: N.Expiry | K1: N.Expiry | L1: N.Expiry | M1: N.Expiry
F2: NIFTY | G2: SENSEX | H2: SENSEX | I2: BANKNIFTY | J2: NIFTY | K2: NIFTY | L2: NIFTY | M2: NIFTY
D3: 1.15 | F3: W.H | G3: W.H | H3: W.H | I3: W.O.H | J3: W.H | K3: W.H | L3: W.H | M3: W.H
E4: =SUM(F4:M4) -> 0.3 | F4: {=IF(Mon!F3="W.H",_xlfn._xlws.FILTER(Margin[Strategy allotment % with hedge],(Margin[Strategy]=Mon!F$5)*(Margin[Index]=Mon!F$2)),_xlfn._xlws.FILTER(Margin[Strategy allotment % without hedge],(Margin[Strategy]=Mon!F$5)*(Margin[Index]=Mon!F$2)))} -> 0 | G4: {=IF(Mon!G3="W.H",_xlfn._xlws.FILTER(Margin[Strategy allotment % with hedge],(Margin[Strategy]=Mon!G$5)*(Margin[Index]=Mon!G$2)),_xlfn._xlws.FILTER(Margin[Strategy allotment % without hedge],(Margin[Strategy]=Mon!G$5)*(Margin[Index]=Mon!G$2)))} -> 0 | H4: {=IF(Mon!H3="W.H",_xlfn._xlws.FILTER(Margin[Strategy allotment % with hedge],(Margin[Strategy]=Mon!H$5)*(Margin[Index]=Mon!H$2)),_xlfn._xlws.FILTER(Margin[Strategy allotment % without hedge],(Margin[Strategy]=Mon!H$5)*(Margin[Index]=Mon!H$2)))} -> 0.1 | I4: {=IF(Mon!I3="W.H",_xlfn._xlws.FILTER(Margin[Strategy allotment % with hedge],(Margin[Strategy]=Mon!I$5)*(Margin[Index]=Mon!I$2)),_xlfn._xlws.FILTER(Margin[Strategy allotment % without hedge],(Margin[Strategy]=Mon!I$5)*(Margin[Index]=Mon!I$2)))} -> 0.1 | J4: {=IF(Mon!J3="W.H",_xlfn._xlws.FILTER(Margin[Strategy allotment % with hedge],(Margin[Strategy]=Mon!J$5)*(Margin[Index]=Mon!J$2)),_xlfn._xlws.FILTER(Margin[Strategy allotment % without hedge],(Margin[Strategy]=Mon!J$5)*(Margin[Index]=Mon!J$2)))} -> 0.1 | K4: {=IF(Mon!K3="W.H",_xlfn._xlws.FILTER(Margin[Strategy allotment % with hedge],(Margin[Strategy]=Mon!K$5)*(Margin[Index]=Mon!K$2)),_xlfn._xlws.FILTER(Margin[Strategy allotment % without hedge],(Margin[Strategy]=Mon!K$5)*(Margin[Index]=Mon!K$2)))} -> 0 | L4: {=IF(Mon!L3="W.H",_xlfn._xlws.FILTER(Margin[Strategy allotment % with hedge],(Margin[Strategy]=Mon!L$5)*(Margin[Index]=Mon!L$2)),_xlfn._xlws.FILTER(Margin[Strategy allotment % without hedge],(Margin[Strategy]=Mon!L$5)*(Margin[Index]=Mon!L$2)))} -> 0 | M4: {=IF(Mon!M3="W.H",_xlfn._xlws.FILTER(Margin[Strategy allotment % with hedge],(Margin[Strategy]=Mon!M$5)*(Margin[Index]=Mon!M$2)),_xlfn._xlws.FILTER(Margin[Strategy allotment % without hedge],(Margin[Strategy]=Mon!M$5)*(Margin[Index]=Mon!M$2)))} -> 0
C5: Client ID | D5: Fund | E5: % | F5: MJ | G5: OI | H5: DYNAMIC SL | I5: DYNAMIC SL | J5: DYNAMIC SL | K5: NFBT RB | L5: NFBT TR | M5: NFBT BTF
A6: =_xlfn.XLOOKUP(C6,'OI QTY'!$O$5:$O$21,'OI QTY'!$N$5:$N$21,"") -> H | B6: =IF(C6="",0,1) -> 1 | C6: OWN | D6: {=(_xlfn._xlws.FILTER(Fund[Margin],Fund[Client Id]=C6))/10000000} -> 7.5 | F6: {=IFERROR(IF(ROUNDUP((Client_Margin($C6)*Alloted(F$3,F$2,F$5)/Get_Margin(F$3,F$2,F$5,F$1)),0)*Get_Margin(F$3,F$2,F$5,F$1)>((Client_Margin($C6)*Alloted(F$3,F$2,F$5)/Get_Margin(F$3,F$2,F$5,F$1))*Get_Margin(F$3,F$2,F$5,F$1))*$D$3,ROUNDDOWN((Client_Margin($C6)*Alloted(F$3,F$2,F$5)/Get_Margin(F$3,F$2,F$5,F$1)),0),ROUNDUP((Client_Margin($C6)*Alloted(F$3,F$2,F$5)/Get_Margin(F$3,F$2,F$5,F$1)),0)),"-")} -> - | G6: {=IFERROR(IF(ROUNDUP((Client_Margin($C6)*Alloted(G$3,G$2,G$5)/Get_Margin(G$3,G$2,G$5,G$1)),0)*Get_Margin(G$3,G$2,G$5,G$1)>((Client_Margin($C6)*Alloted(G$3,G$2,G$5)/Get_Margin(G$3,G$2,G$5,G$1))*Get_Margin(G$3,G$2,G$5,G$1))*$D$3,ROUNDDOWN((Client_Margin($C6)*Alloted(G$3,G$2,G$5)/Get_Margin(G$3,G$2,G$5,G$1)),0),ROUNDUP((Client_Margin($C6)*Alloted(G$3,G$2,G$5)/Get_Margin(G$3,G$2,G$5,G$1)),0)),"-")} -> - | H6: {=IFERROR(IF(ROUNDUP((Client_Margin($C6)*Alloted(H$3,H$2,H$5)/Get_Margin(H$3,H$2,H$5,H$1)),0)*Get_Margin(H$3,H$2,H$5,H$1)>((Client_Margin($C6)*Alloted(H$3,H$2,H$5)/Get_Margin(H$3,H$2,H$5,H$1))*Get_Margin(H$3,H$2,H$5,H$1))*$D$3,ROUNDDOWN((Client_Margin($C6)*Alloted(H$3,H$2,H$5)/Get_Margin(H$3,H$2,H$5,H$1)),0),ROUNDUP((Client_Margin($C6)*Alloted(H$3,H$2,H$5)/Get_Margin(H$3,H$2,H$5,H$1)),0)),"-")} -> 11 | I6: {=IFERROR(IF(ROUNDUP((Client_Margin($C6)*Alloted(I$3,I$2,I$5)/Get_Margin(I$3,I$2,I$5,I$1)),0)*Get_Margin(I$3,I$2,I$5,I$1)>((Client_Margin($C6)*Alloted(I$3,I$2,I$5)/Get_Margin(I$3,I$2,I$5,I$1))*Get_Margin(I$3,I$2,I$5,I$1))*$D$3,ROUNDDOWN((Client_Margin($C6)*Alloted(I$3,I$2,I$5)/Get_Margin(I$3,I$2,I$5,I$1)),0),ROUNDUP((Client_Margin($C6)*Alloted(I$3,I$2,I$5)/Get_Margin(I$3,I$2,I$5,I$1)),0)),"-")} -> 4 | J6: {=IFERROR(IF(ROUNDUP((Client_Margin($C6)*Alloted(J$3,J$2,J$5)/Get_Margin(J$3,J$2,J$5,J$1)),0)*Get_Margin(J$3,J$2,J$5,J$1)>((Client_Margin($C6)*Alloted(J$3,J$2,J$5)/Get_Margin(J$3,J$2,J$5,J$1))*Get_Margin(J$3,J$2,J$5,J$1))*$D$3,ROUNDDOWN((Client_Margin($C6)*Alloted(J$3,J$2,J$5)/Get_Margin(J$3,J$2,J$5,J$1)),0),ROUNDUP((Client_Margin($C6)*Alloted(J$3,J$2,J$5)/Get_Margin(J$3,J$2,J$5,J$1)),0)),"-")} -> 5 | K6: {=IFERROR(IF(ROUNDUP((Client_Margin($C6)*Alloted(K$3,K$2,K$5)/Get_Margin(K$3,K$2,K$5,K$1)),0)*Get_Margin(K$3,K$2,K$5,K$1)>((Client_Margin($C6)*Alloted(K$3,K$2,K$5)/Get_Margin(K$3,K$2,K$5,K$1))*Get_Margin(K$3,K$2,K$5,K$1))*$D$3,ROUNDDOWN((Client_Margin($C6)*Alloted(K$3,K$2,K$5)/Get_Margin(K$3,K$2,K$5,K$1)),0),ROUNDUP((Client_Margin($C6)*Alloted(K$3,K$2,K$5)/Get_Margin(K$3,K$2,K$5,K$1)),0)),"-")} -> 0 | L6: {=IFERROR(IF(ROUNDUP((Client_Margin($C6)*Alloted(L$3,L$2,L$5)/Get_Margin(L$3,L$2,L$5,L$1)),0)*Get_Margin(L$3,L$2,L$5,L$1)>((Client_Margin($C6)*Alloted(L$3,L$2,L$5)/Get_Margin(L$3,L$2,L$5,L$1))*Get_Margin(L$3,L$2,L$5,L$1))*$D$3,ROUNDDOWN((Client_Margin($C6)*Alloted(L$3,L$2,L$5)/Get_Margin(L$3,L$2,L$5,L$1)),0),ROUNDUP((Client_Margin($C6)*Alloted(L$3,L$2,L$5)/Get_Margin(L$3,L$2,L$5,L$1)),0)),"-")} -> 0 | M6: {=IFERROR(IF(ROUNDUP((Client_Margin($C6)*Alloted(M$3,M$2,M$5)/Get_Margin(M$3,M$2,M$5,M$1)),0)*Get_Margin(M$3,M$2,M$5,M$1)>((Client_Margin($C6)*Alloted(M$3,M$2,M$5)/Get_Margin(M$3,M$2,M$5,M$1))*Get_Margin(M$3,M$2,M$5,M$1))*$D$3,ROUNDDOWN((Client_Margin($C6)*Alloted(M$3,M$2,M$5)/Get_Margin(M$3,M$2,M$5,M$1)),0),ROUNDUP((Client_Margin($C6)*Alloted(M$3,M$2,M$5)/Get_Margin(M$3,M$2,M$5,M$1)),0)),"-")} -> 0
A7: =_xlfn.XLOOKUP(C7,'OI QTY'!$O$5:$O$21,'OI QTY'!$N$5:$N$21,"") -> 0 | B7: =IF(C7="",0,1) -> 0 | E7: =SUM(F7:M7) -> 0.30858667 | F7: {=IFERROR((_xlfn._xlws.FILTER(INDEX(Margin[],0,MATCH(F$1&"_"&F$3,Margin[#Headers],0)),(Margin[Index]=F$2)*(Margin[Strategy]=F$5))*F6)/Client_Margin($C6),"-")} -> - | G7: {=IFERROR((_xlfn._xlws.FILTER(INDEX(Margin[],0,MATCH(G$1&"_"&G$3,Margin[#Headers],0)),(Margin[Index]=G$2)*(Margin[Strategy]=G$5))*G6)/Client_Margin($C6),"-")} -> - | H7: {=IFERROR((_xlfn._xlws.FILTER(INDEX(Margin[],0,MATCH(H$1&"_"&H$3,Margin[#Headers],0)),(Margin[Index]=H$2)*(Margin[Strategy]=H$5))*H6)/Client_Margin($C6),"-")} -> 0.10208 | I7: {=IFERROR((_xlfn._xlws.FILTER(INDEX(Margin[],0,MATCH(I$1&"_"&I$3,Margin[#Headers],0)),(Margin[Index]=I$2)*(Margin[Strategy]=I$5))*I6)/Client_Margin($C6),"-")} -> 0.09984 | J7: {=IFERROR((_xlfn._xlws.FILTER(INDEX(Margin[],0,MATCH(J$1&"_"&J$3,Margin[#Headers],0)),(Margin[Index]=J$2)*(Margin[Strategy]=J$5))*J6)/Client_Margin($C6),"-")} -> 0.10666667 | K7: {=IFERROR((_xlfn._xlws.FILTER(INDEX(Margin[],0,MATCH(K$1&"_"&K$3,Margin[#Headers],0)),(Margin[Index]=K$2)*(Margin[Strategy]=K$5))*K6)/Client_Margin($C6),"-")} -> 0 | L7: {=IFERROR((_xlfn._xlws.FILTER(INDEX(Margin[],0,MATCH(L$1&"_"&L$3,Margin[#Headers],0)),(Margin[Index]=L$2)*(Margin[Strategy]=L$5))*L6)/Client_Margin($C6),"-")} -> 0 | M7: {=IFERROR((_xlfn._xlws.FILTER(INDEX(Margin[],0,MATCH(M$1&"_"&M$3,Margin[#Headers],0)),(Margin[Index]=M$2)*(Margin[Strategy]=M$5))*M6)/Client_Margin($C6),"-")} -> 0
A8: =_xlfn.XLOOKUP(C8,'OI QTY'!$O$5:$O$21,'OI QTY'!$N$5:$N$21,"") | B8: =IF(C8="",0,1) -> 1 | C8: ITC2472 | D8: {=(_xlfn._xlws.FILTER(Fund[Margin],Fund[Client Id]=C8))/10000000} -> 6.8 | F8: {=IFERROR(IF(ROUNDUP((Client_Margin($C8)*Alloted(F$3,F$2,F$5)/Get_Margin(F$3,F$2,F$5,F$1)),0)*Get_Margin(F$3,F$2,F$5,F$1)>((Client_Margin($C8)*Alloted(F$3,F$2,F$5)/Get_Margin(F$3,F$2,F$5,F$1))*Get_Margin(F$3,F$2,F$5,F$1))*$D$3,ROUNDDOWN((Client_Margin($C8)*Alloted(F$3,F$2,F$5)/Get_Margin(F$3,F$2,F$5,F$1)),0),ROUNDUP((Client_Margin($C8)*Alloted(F$3,F$2,F$5)/Get_Margin(F$3,F$2,F$5,F$1)),0)),"-")} -> - | G8: {=IFERROR(IF(ROUNDUP((Client_Margin($C8)*Alloted(G$3,G$2,G$5)/Get_Margin(G$3,G$2,G$5,G$1)),0)*Get_Margin(G$3,G$2,G$5,G$1)>((Client_Margin($C8)*Alloted(G$3,G$2,G$5)/Get_Margin(G$3,G$2,G$5,G$1))*Get_Margin(G$3,G$2,G$5,G$1))*$D$3,ROUNDDOWN((Client_Margin($C8)*Alloted(G$3,G$2,G$5)/Get_Margin(G$3,G$2,G$5,G$1)),0),ROUNDUP((Client_Margin($C8)*Alloted(G$3,G$2,G$5)/Get_Margin(G$3,G$2,G$5,G$1)),0)),"-")} -> - | H8: {=IFERROR(IF(ROUNDUP((Client_Margin($C8)*Alloted(H$3,H$2,H$5)/Get_Margin(H$3,H$2,H$5,H$1)),0)*Get_Margin(H$3,H$2,H$5,H$1)>((Client_Margin($C8)*Alloted(H$3,H$2,H$5)/Get_Margin(H$3,H$2,H$5,H$1))*Get_Margin(H$3,H$2,H$5,H$1))*$D$3,ROUNDDOWN((Client_Margin($C8)*Alloted(H$3,H$2,H$5)/Get_Margin(H$3,H$2,H$5,H$1)),0),ROUNDUP((Client_Margin($C8)*Alloted(H$3,H$2,H$5)/Get_Margin(H$3,H$2,H$5,H$1)),0)),"-")} -> 10 | I8: {=IFERROR(IF(ROUNDUP((Client_Margin($C8)*Alloted(I$3,I$2,I$5)/Get_Margin(I$3,I$2,I$5,I$1)),0)*Get_Margin(I$3,I$2,I$5,I$1)>((Client_Margin($C8)*Alloted(I$3,I$2,I$5)/Get_Margin(I$3,I$2,I$5,I$1))*Get_Margin(I$3,I$2,I$5,I$1))*$D$3,ROUNDDOWN((Client_Margin($C8)*Alloted(I$3,I$2,I$5)/Get_Margin(I$3,I$2,I$5,I$1)),0),ROUNDUP((Client_Margin($C8)*Alloted(I$3,I$2,I$5)/Get_Margin(I$3,I$2,I$5,I$1)),0)),"-")} -> 4 | J8: {=IFERROR(IF(ROUNDUP((Client_Margin($C8)*Alloted(J$3,J$2,J$5)/Get_Margin(J$3,J$2,J$5,J$1)),0)*Get_Margin(J$3,J$2,J$5,J$1)>((Client_Margin($C8)*Alloted(J$3,J$2,J$5)/Get_Margin(J$3,J$2,J$5,J$1))*Get_Margin(J$3,J$2,J$5,J$1))*$D$3,ROUNDDOWN((Client_Margin($C8)*Alloted(J$3,J$2,J$5)/Get_Margin(J$3,J$2,J$5,J$1)),0),ROUNDUP((Client_Margin($C8)*Alloted(J$3,J$2,J$5)/Get_Margin(J$3,J$2,J$5,J$1)),0)),"-")} -> 4 | K8: {=IFERROR(IF(ROUNDUP((Client_Margin($C8)*Alloted(K$3,K$2,K$5)/Get_Margin(K$3,K$2,K$5,K$1)),0)*Get_Margin(K$3,K$2,K$5,K$1)>((Client_Margin($C8)*Alloted(K$3,K$2,K$5)/Get_Margin(K$3,K$2,K$5,K$1))*Get_Margin(K$3,K$2,K$5,K$1))*$D$3,ROUNDDOWN((Client_Margin($C8)*Alloted(K$3,K$2,K$5)/Get_Margin(K$3,K$2,K$5,K$1)),0),ROUNDUP((Client_Margin($C8)*Alloted(K$3,K$2,K$5)/Get_Margin(K$3,K$2,K$5,K$1)),0)),"-")} -> 0 | L8: {=IFERROR(IF(ROUNDUP((Client_Margin($C8)*Alloted(L$3,L$2,L$5)/Get_Margin(L$3,L$2,L$5,L$1)),0)*Get_Margin(L$3,L$2,L$5,L$1)>((Client_Margin($C8)*Alloted(L$3,L$2,L$5)/Get_Margin(L$3,L$2,L$5,L$1))*Get_Margin(L$3,L$2,L$5,L$1))*$D$3,ROUNDDOWN((Client_Margin($C8)*Alloted(L$3,L$2,L$5)/Get_Margin(L$3,L$2,L$5,L$1)),0),ROUNDUP((Client_Margin($C8)*Alloted(L$3,L$2,L$5)/Get_Margin(L$3,L$2,L$5,L$1)),0)),"-")} -> 0 | M8: {=IFERROR(IF(ROUNDUP((Client_Margin($C8)*Alloted(M$3,M$2,M$5)/Get_Margin(M$3,M$2,M$5,M$1)),0)*Get_Margin(M$3,M$2,M$5,M$1)>((Client_Margin($C8)*Alloted(M$3,M$2,M$5)/Get_Margin(M$3,M$2,M$5,M$1))*Get_Margin(M$3,M$2,M$5,M$1))*$D$3,ROUNDDOWN((Client_Margin($C8)*Alloted(M$3,M$2,M$5)/Get_Margin(M$3,M$2,M$5,M$1)),0),ROUNDUP((Client_Margin($C8)*Alloted(M$3,M$2,M$5)/Get_Margin(M$3,M$2,M$5,M$1)),0)),"-")} -> 0
A9: =_xlfn.XLOOKUP(C9,'OI QTY'!$O$5:$O$21,'OI QTY'!$N$5:$N$21,"") -> 0 | B9: =IF(C9="",0,1) -> 0 | E9: =SUM(F9:M9) -> 0.30658824 | F9: {=IFERROR((_xlfn._xlws.FILTER(INDEX(Margin[],0,MATCH(F$1&"_"&F$3,Margin[#Headers],0)),(Margin[Index]=F$2)*(Margin[Strategy]=F$5))*F8)/Client_Margin($C8),"-")} -> - | G9: {=IFERROR((_xlfn._xlws.FILTER(INDEX(Margin[],0,MATCH(G$1&"_"&G$3,Margin[#Headers],0)),(Margin[Index]=G$2)*(Margin[Strategy]=G$5))*G8)/Client_Margin($C8),"-")} -> - | H9: {=IFERROR((_xlfn._xlws.FILTER(INDEX(Margin[],0,MATCH(H$1&"_"&H$3,Margin[#Headers],0)),(Margin[Index]=H$2)*(Margin[Strategy]=H$5))*H8)/Client_Margin($C8),"-")} -> 0.10235294 | I9: {=IFERROR((_xlfn._xlws.FILTER(INDEX(Margin[],0,MATCH(I$1&"_"&I$3,Margin[#Headers],0)),(Margin[Index]=I$2)*(Margin[Strategy]=I$5))*I8)/Client_Margin($C8),"-")} -> 0.11011765 | J9: {=IFERROR((_xlfn._xlws.FILTER(INDEX(Margin[],0,MATCH(J$1&"_"&J$3,Margin[#Headers],0)),(Margin[Index]=J$2)*(Margin[Strategy]=J$5))*J8)/Client_Margin($C8),"-")} -> 0.094117647 | K9: {=IFERROR((_xlfn._xlws.FILTER(INDEX(Margin[],0,MATCH(K$1&"_"&K$3,Margin[#Headers],0)),(Margin[Index]=K$2)*(Margin[Strategy]=K$5))*K8)/Client_Margin($C8),"-")} -> 0 | L9: {=IFERROR((_xlfn._xlws.FILTER(INDEX(Margin[],0,MATCH(L$1&"_"&L$3,Margin[#Headers],0)),(Margin[Index]=L$2)*(Margin[Strategy]=L$5))*L8)/Client_Margin($C8),"-")} -> 0 | M9: {=IFERROR((_xlfn._xlws.FILTER(INDEX(Margin[],0,MATCH(M$1&"_"&M$3,Margin[#Headers],0)),(Margin[Index]=M$2)*(Margin[Strategy]=M$5))*M8)/Client_Margin($C8),"-")} -> 0
A10: =_xlfn.XLOOKUP(C10,'OI QTY'!$O$5:$O$21,'OI QTY'!$N$5:$N$21,"") -> M | B10: =IF(C10="",0,1) -> 1 | C10: MOSTI23482 | D10: {=(_xlfn._xlws.FILTER(Fund[Margin],Fund[Client Id]=C10))/10000000} -> 4.6 | F10: {=IFERROR(IF(ROUNDUP((Client_Margin($C10)*Alloted(F$3,F$2,F$5)/Get_Margin(F$3,F$2,F$5,F$1)),0)*Get_Margin(F$3,F$2,F$5,F$1)>((Client_Margin($C10)*Alloted(F$3,F$2,F$5)/Get_Margin(F$3,F$2,F$5,F$1))*Get_Margin(F$3,F$2,F$5,F$1))*$D$3,ROUNDDOWN((Client_Margin($C10)*Alloted(F$3,F$2,F$5)/Get_Margin(F$3,F$2,F$5,F$1)),0),ROUNDUP((Client_Margin($C10)*Alloted(F$3,F$2,F$5)/Get_Margin(F$3,F$2,F$5,F$1)),0)),"-")} -> - | G10: {=IFERROR(IF(ROUNDUP((Client_Margin($C10)*Alloted(G$3,G$2,G$5)/Get_Margin(G$3,G$2,G$5,G$1)),0)*Get_Margin(G$3,G$2,G$5,G$1)>((Client_Margin($C10)*Alloted(G$3,G$2,G$5)/Get_Margin(G$3,G$2,G$5,G$1))*Get_Margin(G$3,G$2,G$5,G$1))*$D$3,ROUNDDOWN((Client_Margin($C10)*Alloted(G$3,G$2,G$5)/Get_Margin(G$3,G$2,G$5,G$1)),0),ROUNDUP((Client_Margin($C10)*Alloted(G$3,G$2,G$5)/Get_Margin(G$3,G$2,G$5,G$1)),0)),"-")} -> - | H10: {=IFERROR(IF(ROUNDUP((Client_Margin($C10)*Alloted(H$3,H$2,H$5)/Get_Margin(H$3,H$2,H$5,H$1)),0)*Get_Margin(H$3,H$2,H$5,H$1)>((Client_Margin($C10)*Alloted(H$3,H$2,H$5)/Get_Margin(H$3,H$2,H$5,H$1))*Get_Margin(H$3,H$2,H$5,H$1))*$D$3,ROUNDDOWN((Client_Margin($C10)*Alloted(H$3,H$2,H$5)/Get_Margin(H$3,H$2,H$5,H$1)),0),ROUNDUP((Client_Margin($C10)*Alloted(H$3,H$2,H$5)/Get_Margin(H$3,H$2,H$5,H$1)),0)),"-")} -> 7 | I10: {=IFERROR(IF(ROUNDUP((Client_Margin($C10)*Alloted(I$3,I$2,I$5)/Get_Margin(I$3,I$2,I$5,I$1)),0)*Get_Margin(I$3,I$2,I$5,I$1)>((Client_Margin($C10)*Alloted(I$3,I$2,I$5)/Get_Margin(I$3,I$2,I$5,I$1))*Get_Margin(I$3,I$2,I$5,I$1))*$D$3,ROUNDDOWN((Client_Margin($C10)*Alloted(I$3,I$2,I$5)/Get_Margin(I$3,I$2,I$5,I$1)),0),ROUNDUP((Client_Margin($C10)*Alloted(I$3,I$2,I$5)/Get_Margin(I$3,I$2,I$5,I$1)),0)),"-")} -> 2 | J10: {=IFERROR(IF(ROUNDUP((Client_Margin($C10)*Alloted(J$3,J$2,J$5)/Get_Margin(J$3,J$2,J$5,J$1)),0)*Get_Margin(J$3,J$2,J$5,J$1)>((Client_Margin($C10)*Alloted(J$3,J$2,J$5)/Get_Margin(J$3,J$2,J$5,J$1))*Get_Margin(J$3,J$2,J$5,J$1))*$D$3,ROUNDDOWN((Client_Margin($C10)*Alloted(J$3,J$2,J$5)/Get_Margin(J$3,J$2,J$5,J$1)),0),ROUNDUP((Client_Margin($C10)*Alloted(J$3,J$2,J$5)/Get_Margin(J$3,J$2,J$5,J$1)),0)),"-")} -> 3 | K10: {=IFERROR(IF(ROUNDUP((Client_Margin($C10)*Alloted(K$3,K$2,K$5)/Get_Margin(K$3,K$2,K$5,K$1)),0)*Get_Margin(K$3,K$2,K$5,K$1)>((Client_Margin($C10)*Alloted(K$3,K$2,K$5)/Get_Margin(K$3,K$2,K$5,K$1))*Get_Margin(K$3,K$2,K$5,K$1))*$D$3,ROUNDDOWN((Client_Margin($C10)*Alloted(K$3,K$2,K$5)/Get_Margin(K$3,K$2,K$5,K$1)),0),ROUNDUP((Client_Margin($C10)*Alloted(K$3,K$2,K$5)/Get_Margin(K$3,K$2,K$5,K$1)),0)),"-")} -> 0 | L10: {=IFERROR(IF(ROUNDUP((Client_Margin($C10)*Alloted(L$3,L$2,L$5)/Get_Margin(L$3,L$2,L$5,L$1)),0)*Get_Margin(L$3,L$2,L$5,L$1)>((Client_Margin($C10)*Alloted(L$3,L$2,L$5)/Get_Margin(L$3,L$2,L$5,L$1))*Get_Margin(L$3,L$2,L$5,L$1))*$D$3,ROUNDDOWN((Client_Margin($C10)*Alloted(L$3,L$2,L$5)/Get_Margin(L$3,L$2,L$5,L$1)),0),ROUNDUP((Client_Margin($C10)*Alloted(L$3,L$2,L$5)/Get_Margin(L$3,L$2,L$5,L$1)),0)),"-")} -> 0 | M10: {=IFERROR(IF(ROUNDUP((Client_Margin($C10)*Alloted(M$3,M$2,M$5)/Get_Margin(M$3,M$2,M$5,M$1)),0)*Get_Margin(M$3,M$2,M$5,M$1)>((Client_Margin($C10)*Alloted(M$3,M$2,M$5)/Get_Margin(M$3,M$2,M$5,M$1))*Get_Margin(M$3,M$2,M$5,M$1))*$D$3,ROUNDDOWN((Client_Margin($C10)*Alloted(M$3,M$2,M$5)/Get_Margin(M$3,M$2,M$5,M$1)),0),ROUNDUP((Client_Margin($C10)*Alloted(M$3,M$2,M$5)/Get_Margin(M$3,M$2,M$5,M$1)),0)),"-")} -> 0
A11: =_xlfn.XLOOKUP(C11,'OI QTY'!$O$5:$O$21,'OI QTY'!$N$5:$N$21,"") -> 0 | B11: =IF(C11="",0,1) -> 0 | E11: =SUM(F11:M11) -> 0.29165217 | F11: {=IFERROR((_xlfn._xlws.FILTER(INDEX(Margin[],0,MATCH(F$1&"_"&F$3,Margin[#Headers],0)),(Margin[Index]=F$2)*(Margin[Strategy]=F$5))*F10)/Client_Margin($C10),"-")} -> - | G11: {=IFERROR((_xlfn._xlws.FILTER(INDEX(Margin[],0,MATCH(G$1&"_"&G$3,Margin[#Headers],0)),(Margin[Index]=G$2)*(Margin[Strategy]=G$5))*G10)/Client_Margin($C10),"-")} -> - | H11: {=IFERROR((_xlfn._xlws.FILTER(INDEX(Margin[],0,MATCH(H$1&"_"&H$3,Margin[#Headers],0)),(Margin[Index]=H$2)*(Margin[Strategy]=H$5))*H10)/Client_Margin($C10),"-")} -> 0.10591304 | I11: {=IFERROR((_xlfn._xlws.FILTER(INDEX(Margin[],0,MATCH(I$1&"_"&I$3,Margin[#Headers],0)),(Margin[Index]=I$2)*(Margin[Strategy]=I$5))*I10)/Client_Margin($C10),"-")} -> 0.081391304 | J11: {=IFERROR((_xlfn._xlws.FILTER(INDEX(Margin[],0,MATCH(J$1&"_"&J$3,Margin[#Headers],0)),(Margin[Index]=J$2)*(Margin[Strategy]=J$5))*J10)/Client_Margin($C10),"-")} -> 0.10434783 | K11: {=IFERROR((_xlfn._xlws.FILTER(INDEX(Margin[],0,MATCH(K$1&"_"&K$3,Margin[#Headers],0)),(Margin[Index]=K$2)*(Margin[Strategy]=K$5))*K10)/Client_Margin($C10),"-")} -> 0 | L11: {=IFERROR((_xlfn._xlws.FILTER(INDEX(Margin[],0,MATCH(L$1&"_"&L$3,Margin[#Headers],0)),(Margin[Index]=L$2)*(Margin[Strategy]=L$5))*L10)/Client_Margin($C10),"-")} -> 0 | M11: {=IFERROR((_xlfn._xlws.FILTER(INDEX(Margin[],0,MATCH(M$1&"_"&M$3,Margin[#Headers],0)),(Margin[Index]=M$2)*(Margin[Strategy]=M$5))*M10)/Client_Margin($C10),"-")} -> 0
A12: =_xlfn.XLOOKUP(C12,'OI QTY'!$O$5:$O$21,'OI QTY'!$N$5:$N$21,"") -> M | B12: =IF(C12="",0,1) -> 1 | C12: MOSTI23035 | D12: {=(_xlfn._xlws.FILTER(Fund[Margin],Fund[Client Id]=C12))/10000000} -> 7 | F12: {=IFERROR(IF(ROUNDUP((Client_Margin($C12)*Alloted(F$3,F$2,F$5)/Get_Margin(F$3,F$2,F$5,F$1)),0)*Get_Margin(F$3,F$2,F$5,F$1)>((Client_Margin($C12)*Alloted(F$3,F$2,F$5)/Get_Margin(F$3,F$2,F$5,F$1))*Get_Margin(F$3,F$2,F$5,F$1))*$D$3,ROUNDDOWN((Client_Margin($C12)*Alloted(F$3,F$2,F$5)/Get_Margin(F$3,F$2,F$5,F$1)),0),ROUNDUP((Client_Margin($C12)*Alloted(F$3,F$2,F$5)/Get_Margin(F$3,F$2,F$5,F$1)),0)),"-")} -> - | G12: {=IFERROR(IF(ROUNDUP((Client_Margin($C12)*Alloted(G$3,G$2,G$5)/Get_Margin(G$3,G$2,G$5,G$1)),0)*Get_Margin(G$3,G$2,G$5,G$1)>((Client_Margin($C12)*Alloted(G$3,G$2,G$5)/Get_Margin(G$3,G$2,G$5,G$1))*Get_Margin(G$3,G$2,G$5,G$1))*$D$3,ROUNDDOWN((Client_Margin($C12)*Alloted(G$3,G$2,G$5)/Get_Margin(G$3,G$2,G$5,G$1)),0),ROUNDUP((Client_Margin($C12)*Alloted(G$3,G$2,G$5)/Get_Margin(G$3,G$2,G$5,G$1)),0)),"-")} -> - | H12: {=IFERROR(IF(ROUNDUP((Client_Margin($C12)*Alloted(H$3,H$2,H$5)/Get_Margin(H$3,H$2,H$5,H$1)),0)*Get_Margin(H$3,H$2,H$5,H$1)>((Client_Margin($C12)*Alloted(H$3,H$2,H$5)/Get_Margin(H$3,H$2,H$5,H$1))*Get_Margin(H$3,H$2,H$5,H$1))*$D$3,ROUNDDOWN((Client_Margin($C12)*Alloted(H$3,H$2,H$5)/Get_Margin(H$3,H$2,H$5,H$1)),0),ROUNDUP((Client_Margin($C12)*Alloted(H$3,H$2,H$5)/Get_Margin(H$3,H$2,H$5,H$1)),0)),"-")} -> 11 | I12: {=IFERROR(IF(ROUNDUP((Client_Margin($C12)*Alloted(I$3,I$2,I$5)/Get_Margin(I$3,I$2,I$5,I$1)),0)*Get_Margin(I$3,I$2,I$5,I$1)>((Client_Margin($C12)*Alloted(I$3,I$2,I$5)/Get_Margin(I$3,I$2,I$5,I$1))*Get_Margin(I$3,I$2,I$5,I$1))*$D$3,ROUNDDOWN((Client_Margin($C12)*Alloted(I$3,I$2,I$5)/Get_Margin(I$3,I$2,I$5,I$1)),0),ROUNDUP((Client_Margin($C12)*Alloted(I$3,I$2,I$5)/Get_Margin(I$3,I$2,I$5,I$1)),0)),"-")} -> 4 | J12: {=IFERROR(IF(ROUNDUP((Client_Margin($C12)*Alloted(J$3,J$2,J$5)/Get_Margin(J$3,J$2,J$5,J$1)),0)*Get_Margin(J$3,J$2,J$5,J$1)>((Client_Margin($C12)*Alloted(J$3,J$2,J$5)/Get_Margin(J$3,J$2,J$5,J$1))*Get_Margin(J$3,J$2,J$5,J$1))*$D$3,ROUNDDOWN((Client_Margin($C12)*Alloted(J$3,J$2,J$5)/Get_Margin(J$3,J$2,J$5,J$1)),0),ROUNDUP((Client_Margin($C12)*Alloted(J$3,J$2,J$5)/Get_Margin(J$3,J$2,J$5,J$1)),0)),"-")} -> 5 | K12: {=IFERROR(IF(ROUNDUP((Client_Margin($C12)*Alloted(K$3,K$2,K$5)/Get_Margin(K$3,K$2,K$5,K$1)),0)*Get_Margin(K$3,K$2,K$5,K$1)>((Client_Margin($C12)*Alloted(K$3,K$2,K$5)/Get_Margin(K$3,K$2,K$5,K$1))*Get_Margin(K$3,K$2,K$5,K$1))*$D$3,ROUNDDOWN((Client_Margin($C12)*Alloted(K$3,K$2,K$5)/Get_Margin(K$3,K$2,K$5,K$1)),0),ROUNDUP((Client_Margin($C12)*Alloted(K$3,K$2,K$5)/Get_Margin(K$3,K$2,K$5,K$1)),0)),"-")} -> 0 | L12: {=IFERROR(IF(ROUNDUP((Client_Margin($C12)*Alloted(L$3,L$2,L$5)/Get_Margin(L$3,L$2,L$5,L$1)),0)*Get_Margin(L$3,L$2,L$5,L$1)>((Client_Margin($C12)*Alloted(L$3,L$2,L$5)/Get_Margin(L$3,L$2,L$5,L$1))*Get_Margin(L$3,L$2,L$5,L$1))*$D$3,ROUNDDOWN((Client_Margin($C12)*Alloted(L$3,L$2,L$5)/Get_Margin(L$3,L$2,L$5,L$1)),0),ROUNDUP((Client_Margin($C12)*Alloted(L$3,L$2,L$5)/Get_Margin(L$3,L$2,L$5,L$1)),0)),"-")} -> 0 | M12: {=IFERROR(IF(ROUNDUP((Client_Margin($C12)*Alloted(M$3,M$2,M$5)/Get_Margin(M$3,M$2,M$5,M$1)),0)*Get_Margin(M$3,M$2,M$5,M$1)>((Client_Margin($C12)*Alloted(M$3,M$2,M$5)/Get_Margin(M$3,M$2,M$5,M$1))*Get_Margin(M$3,M$2,M$5,M$1))*$D$3,ROUNDDOWN((Client_Margin($C12)*Alloted(M$3,M$2,M$5)/Get_Margin(M$3,M$2,M$5,M$1)),0),ROUNDUP((Client_Margin($C12)*Alloted(M$3,M$2,M$5)/Get_Margin(M$3,M$2,M$5,M$1)),0)),"-")} -> 0
A13: =_xlfn.XLOOKUP(C13,'OI QTY'!$O$5:$O$21,'OI QTY'!$N$5:$N$21,"") -> 0 | B13: =IF(C13="",0,1) -> 0 | E13: =SUM(F13:M13) -> 0.33062857 | F13: {=IFERROR((_xlfn._xlws.FILTER(INDEX(Margin[],0,MATCH(F$1&"_"&F$3,Margin[#Headers],0)),(Margin[Index]=F$2)*(Margin[Strategy]=F$5))*F12)/Client_Margin($C12),"-")} -> - | G13: {=IFERROR((_xlfn._xlws.FILTER(INDEX(Margin[],0,MATCH(G$1&"_"&G$3,Margin[#Headers],0)),(Margin[Index]=G$2)*(Margin[Strategy]=G$5))*G12)/Client_Margin($C12),"-")} -> - | H13: {=IFERROR((_xlfn._xlws.FILTER(INDEX(Margin[],0,MATCH(H$1&"_"&H$3,Margin[#Headers],0)),(Margin[Index]=H$2)*(Margin[Strategy]=H$5))*H12)/Client_Margin($C12),"-")} -> 0.10937143 | I13: {=IFERROR((_xlfn._xlws.FILTER(INDEX(Margin[],0,MATCH(I$1&"_"&I$3,Margin[#Headers],0)),(Margin[Index]=I$2)*(Margin[Strategy]=I$5))*I12)/Client_Margin($C12),"-")} -> 0.10697143 | J13: {=IFERROR((_xlfn._xlws.FILTER(INDEX(Margin[],0,MATCH(J$1&"_"&J$3,Margin[#Headers],0)),(Margin[Index]=J$2)*(Margin[Strategy]=J$5))*J12)/Client_Margin($C12),"-")} -> 0.11428571 | K13: {=IFERROR((_xlfn._xlws.FILTER(INDEX(Margin[],0,MATCH(K$1&"_"&K$3,Margin[#Headers],0)),(Margin[Index]=K$2)*(Margin[Strategy]=K$5))*K12)/Client_Margin($C12),"-")} -> 0 | L13: {=IFERROR((_xlfn._xlws.FILTER(INDEX(Margin[],0,MATCH(L$1&"_"&L$3,Margin[#Headers],0)),(Margin[Index]=L$2)*(Margin[Strategy]=L$5))*L12)/Client_Margin($C12),"-")} -> 0 | M13: {=IFERROR((_xlfn._xlws.FILTER(INDEX(Margin[],0,MATCH(M$1&"_"&M$3,Margin[#Headers],0)),(Margin[Index]=M$2)*(Margin[Strategy]=M$5))*M12)/Client_Margin($C12),"-")} -> 0
A14: =_xlfn.XLOOKUP(C14,'OI QTY'!$O$5:$O$21,'OI QTY'!$N$5:$N$21,"") -> M | B14: =IF(C14="",0,1) -> 1 | C14: SAT2484 | D14: {=(_xlfn._xlws.FILTER(Fund[Margin],Fund[Client Id]=C14))/10000000} -> 4 | F14: {=IFERROR(IF(ROUNDUP((Client_Margin($C14)*Alloted(F$3,F$2,F$5)/Get_Margin(F$3,F$2,F$5,F$1)),0)*Get_Margin(F$3,F$2,F$5,F$1)>((Client_Margin($C14)*Alloted(F$3,F$2,F$5)/Get_Margin(F$3,F$2,F$5,F$1))*Get_Margin(F$3,F$2,F$5,F$1))*$D$3,ROUNDDOWN((Client_Margin($C14)*Alloted(F$3,F$2,F$5)/Get_Margin(F$3,F$2,F$5,F$1)),0),ROUNDUP((Client_Margin($C14)*Alloted(F$3,F$2,F$5)/Get_Margin(F$3,F$2,F$5,F$1)),0)),"-")} -> - | G14: {=IFERROR(IF(ROUNDUP((Client_Margin($C14)*Alloted(G$3,G$2,G$5)/Get_Margin(G$3,G$2,G$5,G$1)),0)*Get_Margin(G$3,G$2,G$5,G$1)>((Client_Margin($C14)*Alloted(G$3,G$2,G$5)/Get_Margin(G$3,G$2,G$5,G$1))*Get_Margin(G$3,G$2,G$5,G$1))*$D$3,ROUNDDOWN((Client_Margin($C14)*Alloted(G$3,G$2,G$5)/Get_Margin(G$3,G$2,G$5,G$1)),0),ROUNDUP((Client_Margin($C14)*Alloted(G$3,G$2,G$5)/Get_Margin(G$3,G$2,G$5,G$1)),0)),"-")} -> - | H14: {=IFERROR(IF(ROUNDUP((Client_Margin($C14)*Alloted(H$3,H$2,H$5)/Get_Margin(H$3,H$2,H$5,H$1)),0)*Get_Margin(H$3,H$2,H$5,H$1)>((Client_Margin($C14)*Alloted(H$3,H$2,H$5)/Get_Margin(H$3,H$2,H$5,H$1))*Get_Margin(H$3,H$2,H$5,H$1))*$D$3,ROUNDDOWN((Client_Margin($C14)*Alloted(H$3,H$2,H$5)/Get_Margin(H$3,H$2,H$5,H$1)),0),ROUNDUP((Client_Margin($C14)*Alloted(H$3,H$2,H$5)/Get_Margin(H$3,H$2,H$5,H$1)),0)),"-")} -> 6 | I14: {=IFERROR(IF(ROUNDUP((Client_Margin($C14)*Alloted(I$3,I$2,I$5)/Get_Margin(I$3,I$2,I$5,I$1)),0)*Get_Margin(I$3,I$2,I$5,I$1)>((Client_Margin($C14)*Alloted(I$3,I$2,I$5)/Get_Margin(I$3,I$2,I$5,I$1))*Get_Margin(I$3,I$2,I$5,I$1))*$D$3,ROUNDDOWN((Client_Margin($C14)*Alloted(I$3,I$2,I$5)/Get_Margin(I$3,I$2,I$5,I$1)),0),ROUNDUP((Client_Margin($C14)*Alloted(I$3,I$2,I$5)/Get_Margin(I$3,I$2,I$5,I$1)),0)),"-")} -> 2 | J14: {=IFERROR(IF(ROUNDUP((Client_Margin($C14)*Alloted(J$3,J$2,J$5)/Get_Margin(J$3,J$2,J$5,J$1)),0)*Get_Margin(J$3,J$2,J$5,J$1)>((Client_Margin($C14)*Alloted(J$3,J$2,J$5)/Get_Margin(J$3,J$2,J$5,J$1))*Get_Margin(J$3,J$2,J$5,J$1))*$D$3,ROUNDDOWN((Client_Margin($C14)*Alloted(J$3,J$2,J$5)/Get_Margin(J$3,J$2,J$5,J$1)),0),ROUNDUP((Client_Margin($C14)*Alloted(J$3,J$2,J$5)/Get_Margin(J$3,J$2,J$5,J$1)),0)),"-")} -> 2 | K14: {=IFERROR(IF(ROUNDUP((Client_Margin($C14)*Alloted(K$3,K$2,K$5)/Get_Margin(K$3,K$2,K$5,K$1)),0)*Get_Margin(K$3,K$2,K$5,K$1)>((Client_Margin($C14)*Alloted(K$3,K$2,K$5)/Get_Margin(K$3,K$2,K$5,K$1))*Get_Margin(K$3,K$2,K$5,K$1))*$D$3,ROUNDDOWN((Client_Margin($C14)*Alloted(K$3,K$2,K$5)/Get_Margin(K$3,K$2,K$5,K$1)),0),ROUNDUP((Client_Margin($C14)*Alloted(K$3,K$2,K$5)/Get_Margin(K$3,K$2,K$5,K$1)),0)),"-")} -> 0 | L14: {=IFERROR(IF(ROUNDUP((Client_Margin($C14)*Alloted(L$3,L$2,L$5)/Get_Margin(L$3,L$2,L$5,L$1)),0)*Get_Margin(L$3,L$2,L$5,L$1)>((Client_Margin($C14)*Alloted(L$3,L$2,L$5)/Get_Margin(L$3,L$2,L$5,L$1))*Get_Margin(L$3,L$2,L$5,L$1))*$D$3,ROUNDDOWN((Client_Margin($C14)*Alloted(L$3,L$2,L$5)/Get_Margin(L$3,L$2,L$5,L$1)),0),ROUNDUP((Client_Margin($C14)*Alloted(L$3,L$2,L$5)/Get_Margin(L$3,L$2,L$5,L$1)),0)),"-")} -> 0 | M14: {=IFERROR(IF(ROUNDUP((Client_Margin($C14)*Alloted(M$3,M$2,M$5)/Get_Margin(M$3,M$2,M$5,M$1)),0)*Get_Margin(M$3,M$2,M$5,M$1)>((Client_Margin($C14)*Alloted(M$3,M$2,M$5)/Get_Margin(M$3,M$2,M$5,M$1))*Get_Margin(M$3,M$2,M$5,M$1))*$D$3,ROUNDDOWN((Client_Margin($C14)*Alloted(M$3,M$2,M$5)/Get_Margin(M$3,M$2,M$5,M$1)),0),ROUNDUP((Client_Margin($C14)*Alloted(M$3,M$2,M$5)/Get_Margin(M$3,M$2,M$5,M$1)),0)),"-")} -> 0
A15: =_xlfn.XLOOKUP(C15,'OI QTY'!$O$5:$O$21,'OI QTY'!$N$5:$N$21,"") -> 0 | B15: =IF(C15="",0,1) -> 0 | E15: =SUM(F15:M15) -> 0.278 | F15: {=IFERROR((_xlfn._xlws.FILTER(INDEX(Margin[],0,MATCH(F$1&"_"&F$3,Margin[#Headers],0)),(Margin[Index]=F$2)*(Margin[Strategy]=F$5))*F14)/Client_Margin($C14),"-")} -> - | G15: {=IFERROR((_xlfn._xlws.FILTER(INDEX(Margin[],0,MATCH(G$1&"_"&G$3,Margin[#Headers],0)),(Margin[Index]=G$2)*(Margin[Strategy]=G$5))*G14)/Client_Margin($C14),"-")} -> - | H15: {=IFERROR((_xlfn._xlws.FILTER(INDEX(Margin[],0,MATCH(H$1&"_"&H$3,Margin[#Headers],0)),(Margin[Index]=H$2)*(Margin[Strategy]=H$5))*H14)/Client_Margin($C14),"-")} -> 0.1044 | I15: {=IFERROR((_xlfn._xlws.FILTER(INDEX(Margin[],0,MATCH(I$1&"_"&I$3,Margin[#Headers],0)),(Margin[Index]=I$2)*(Margin[Strategy]=I$5))*I14)/Client_Margin($C14),"-")} -> 0.0936 | J15: {=IFERROR((_xlfn._xlws.FILTER(INDEX(Margin[],0,MATCH(J$1&"_"&J$3,Margin[#Headers],0)),(Margin[Index]=J$2)*(Margin[Strategy]=J$5))*J14)/Client_Margin($C14),"-")} -> 0.08 | K15: {=IFERROR((_xlfn._xlws.FILTER(INDEX(Margin[],0,MATCH(K$1&"_"&K$3,Margin[#Headers],0)),(Margin[Index]=K$2)*(Margin[Strategy]=K$5))*K14)/Client_Margin($C14),"-")} -> 0 | L15: {=IFERROR((_xlfn._xlws.FILTER(INDEX(Margin[],0,MATCH(L$1&"_"&L$3,Margin[#Headers],0)),(Margin[Index]=L$2)*(Margin[Strategy]=L$5))*L14)/Client_Margin($C14),"-")} -> 0 | M15: {=IFERROR((_xlfn._xlws.FILTER(INDEX(Margin[],0,MATCH(M$1&"_"&M$3,Margin[#Headers],0)),(Margin[Index]=M$2)*(Margin[Strategy]=M$5))*M14)/Client_Margin($C14),"-")} -> 0
A16: =_xlfn.XLOOKUP(C16,'OI QTY'!$O$5:$O$21,'OI QTY'!$N$5:$N$21,"") -> M | B16: =IF(C16="",0,1) -> 1 | C16: MOSTI22960 | D16: {=(_xlfn._xlws.FILTER(Fund[Margin],Fund[Client Id]=C16))/10000000} -> 2 | F16: {=IFERROR(IF(ROUNDUP((Client_Margin($C16)*Alloted(F$3,F$2,F$5)/Get_Margin(F$3,F$2,F$5,F$1)),0)*Get_Margin(F$3,F$2,F$5,F$1)>((Client_Margin($C16)*Alloted(F$3,F$2,F$5)/Get_Margin(F$3,F$2,F$5,F$1))*Get_Margin(F$3,F$2,F$5,F$1))*$D$3,ROUNDDOWN((Client_Margin($C16)*Alloted(F$3,F$2,F$5)/Get_Margin(F$3,F$2,F$5,F$1)),0),ROUNDUP((Client_Margin($C16)*Alloted(F$3,F$2,F$5)/Get_Margin(F$3,F$2,F$5,F$1)),0)),"-")} -> - | G16: {=IFERROR(IF(ROUNDUP((Client_Margin($C16)*Alloted(G$3,G$2,G$5)/Get_Margin(G$3,G$2,G$5,G$1)),0)*Get_Margin(G$3,G$2,G$5,G$1)>((Client_Margin($C16)*Alloted(G$3,G$2,G$5)/Get_Margin(G$3,G$2,G$5,G$1))*Get_Margin(G$3,G$2,G$5,G$1))*$D$3,ROUNDDOWN((Client_Margin($C16)*Alloted(G$3,G$2,G$5)/Get_Margin(G$3,G$2,G$5,G$1)),0),ROUNDUP((Client_Margin($C16)*Alloted(G$3,G$2,G$5)/Get_Margin(G$3,G$2,G$5,G$1)),0)),"-")} -> - | H16: {=IFERROR(IF(ROUNDUP((Client_Margin($C16)*Alloted(H$3,H$2,H$5)/Get_Margin(H$3,H$2,H$5,H$1)),0)*Get_Margin(H$3,H$2,H$5,H$1)>((Client_Margin($C16)*Alloted(H$3,H$2,H$5)/Get_Margin(H$3,H$2,H$5,H$1))*Get_Margin(H$3,H$2,H$5,H$1))*$D$3,ROUNDDOWN((Client_Margin($C16)*Alloted(H$3,H$2,H$5)/Get_Margin(H$3,H$2,H$5,H$1)),0),ROUNDUP((Client_Margin($C16)*Alloted(H$3,H$2,H$5)/Get_Margin(H$3,H$2,H$5,H$1)),0)),"-")} -> 3 | I16: {=IFERROR(IF(ROUNDUP((Client_Margin($C16)*Alloted(I$3,I$2,I$5)/Get_Margin(I$3,I$2,I$5,I$1)),0)*Get_Margin(I$3,I$2,I$5,I$1)>((Client_Margin($C16)*Alloted(I$3,I$2,I$5)/Get_Margin(I$3,I$2,I$5,I$1))*Get_Margin(I$3,I$2,I$5,I$1))*$D$3,ROUNDDOWN((Client_Margin($C16)*Alloted(I$3,I$2,I$5)/Get_Margin(I$3,I$2,I$5,I$1)),0),ROUNDUP((Client_Margin($C16)*Alloted(I$3,I$2,I$5)/Get_Margin(I$3,I$2,I$5,I$1)),0)),"-")} -> 1 | J16: {=IFERROR(IF(ROUNDUP((Client_Margin($C16)*Alloted(J$3,J$2,J$5)/Get_Margin(J$3,J$2,J$5,J$1)),0)*Get_Margin(J$3,J$2,J$5,J$1)>((Client_Margin($C16)*Alloted(J$3,J$2,J$5)/Get_Margin(J$3,J$2,J$5,J$1))*Get_Margin(J$3,J$2,J$5,J$1))*$D$3,ROUNDDOWN((Client_Margin($C16)*Alloted(J$3,J$2,J$5)/Get_Margin(J$3,J$2,J$5,J$1)),0),ROUNDUP((Client_Margin($C16)*Alloted(J$3,J$2,J$5)/Get_Margin(J$3,J$2,J$5,J$1)),0)),"-")} -> 1 | K16: {=IFERROR(IF(ROUNDUP((Client_Margin($C16)*Alloted(K$3,K$2,K$5)/Get_Margin(K$3,K$2,K$5,K$1)),0)*Get_Margin(K$3,K$2,K$5,K$1)>((Client_Margin($C16)*Alloted(K$3,K$2,K$5)/Get_Margin(K$3,K$2,K$5,K$1))*Get_Margin(K$3,K$2,K$5,K$1))*$D$3,ROUNDDOWN((Client_Margin($C16)*Alloted(K$3,K$2,K$5)/Get_Margin(K$3,K$2,K$5,K$1)),0),ROUNDUP((Client_Margin($C16)*Alloted(K$3,K$2,K$5)/Get_Margin(K$3,K$2,K$5,K$1)),0)),"-")} -> 0 | L16: {=IFERROR(IF(ROUNDUP((Client_Margin($C16)*Alloted(L$3,L$2,L$5)/Get_Margin(L$3,L$2,L$5,L$1)),0)*Get_Margin(L$3,L$2,L$5,L$1)>((Client_Margin($C16)*Alloted(L$3,L$2,L$5)/Get_Margin(L$3,L$2,L$5,L$1))*Get_Margin(L$3,L$2,L$5,L$1))*$D$3,ROUNDDOWN((Client_Margin($C16)*Alloted(L$3,L$2,L$5)/Get_Margin(L$3,L$2,L$5,L$1)),0),ROUNDUP((Client_Margin($C16)*Alloted(L$3,L$2,L$5)/Get_Margin(L$3,L$2,L$5,L$1)),0)),"-")} -> 0 | M16: {=IFERROR(IF(ROUNDUP((Client_Margin($C16)*Alloted(M$3,M$2,M$5)/Get_Margin(M$3,M$2,M$5,M$1)),0)*Get_Margin(M$3,M$2,M$5,M$1)>((Client_Margin($C16)*Alloted(M$3,M$2,M$5)/Get_Margin(M$3,M$2,M$5,M$1))*Get_Margin(M$3,M$2,M$5,M$1))*$D$3,ROUNDDOWN((Client_Margin($C16)*Alloted(M$3,M$2,M$5)/Get_Margin(M$3,M$2,M$5,M$1)),0),ROUNDUP((Client_Margin($C16)*Alloted(M$3,M$2,M$5)/Get_Margin(M$3,M$2,M$5,M$1)),0)),"-")} -> 0
A17: =_xlfn.XLOOKUP(C17,'OI QTY'!$O$5:$O$21,'OI QTY'!$N$5:$N$21,"") -> 0 | B17: =IF(C17="",0,1) -> 0 | E17: =SUM(F17:M17) -> 0.278 | F17: {=IFERROR((_xlfn._xlws.FILTER(INDEX(Margin[],0,MATCH(F$1&"_"&F$3,Margin[#Headers],0)),(Margin[Index]=F$2)*(Margin[Strategy]=F$5))*F16)/Client_Margin($C16),"-")} -> - | G17: {=IFERROR((_xlfn._xlws.FILTER(INDEX(Margin[],0,MATCH(G$1&"_"&G$3,Margin[#Headers],0)),(Margin[Index]=G$2)*(Margin[Strategy]=G$5))*G16)/Client_Margin($C16),"-")} -> - | H17: {=IFERROR((_xlfn._xlws.FILTER(INDEX(Margin[],0,MATCH(H$1&"_"&H$3,Margin[#Headers],0)),(Margin[Index]=H$2)*(Margin[Strategy]=H$5))*H16)/Client_Margin($C16),"-")} -> 0.1044 | I17: {=IFERROR((_xlfn._xlws.FILTER(INDEX(Margin[],0,MATCH(I$1&"_"&I$3,Margin[#Headers],0)),(Margin[Index]=I$2)*(Margin[Strategy]=I$5))*I16)/Client_Margin($C16),"-")} -> 0.0936 | J17: {=IFERROR((_xlfn._xlws.FILTER(INDEX(Margin[],0,MATCH(J$1&"_"&J$3,Margin[#Headers],0)),(Margin[Index]=J$2)*(Margin[Strategy]=J$5))*J16)/Client_Margin($C16),"-")} -> 0.08 | K17: {=IFERROR((_xlfn._xlws.FILTER(INDEX(Margin[],0,MATCH(K$1&"_"&K$3,Margin[#Headers],0)),(Margin[Index]=K$2)*(Margin[Strategy]=K$5))*K16)/Client_Margin($C16),"-")} -> 0 | L17: {=IFERROR((_xlfn._xlws.FILTER(INDEX(Margin[],0,MATCH(L$1&"_"&L$3,Margin[#Headers],0)),(Margin[Index]=L$2)*(Margin[Strategy]=L$5))*L16)/Client_Margin($C16),"-")} -> 0 | M17: {=IFERROR((_xlfn._xlws.FILTER(INDEX(Margin[],0,MATCH(M$1&"_"&M$3,Margin[#Headers],0)),(Margin[Index]=M$2)*(Margin[Strategy]=M$5))*M16)/Client_Margin($C16),"-")} -> 0
A18: =_xlfn.XLOOKUP(C18,'OI QTY'!$O$5:$O$21,'OI QTY'!$N$5:$N$21,"") | B18: =IF(C18="",0,1) -> 1 | C18: ITC2142 | D18: {=(_xlfn._xlws.FILTER(Fund[Margin],Fund[Client Id]=C18))/10000000} -> 5.1 | F18: {=IFERROR(IF(ROUNDUP((Client_Margin($C18)*Alloted(F$3,F$2,F$5)/Get_Margin(F$3,F$2,F$5,F$1)),0)*Get_Margin(F$3,F$2,F$5,F$1)>((Client_Margin($C18)*Alloted(F$3,F$2,F$5)/Get_Margin(F$3,F$2,F$5,F$1))*Get_Margin(F$3,F$2,F$5,F$1))*$D$3,ROUNDDOWN((Client_Margin($C18)*Alloted(F$3,F$2,F$5)/Get_Margin(F$3,F$2,F$5,F$1)),0),ROUNDUP((Client_Margin($C18)*Alloted(F$3,F$2,F$5)/Get_Margin(F$3,F$2,F$5,F$1)),0)),"-")} -> - | G18: {=IFERROR(IF(ROUNDUP((Client_Margin($C18)*Alloted(G$3,G$2,G$5)/Get_Margin(G$3,G$2,G$5,G$1)),0)*Get_Margin(G$3,G$2,G$5,G$1)>((Client_Margin($C18)*Alloted(G$3,G$2,G$5)/Get_Margin(G$3,G$2,G$5,G$1))*Get_Margin(G$3,G$2,G$5,G$1))*$D$3,ROUNDDOWN((Client_Margin($C18)*Alloted(G$3,G$2,G$5)/Get_Margin(G$3,G$2,G$5,G$1)),0),ROUNDUP((Client_Margin($C18)*Alloted(G$3,G$2,G$5)/Get_Margin(G$3,G$2,G$5,G$1)),0)),"-")} -> - | H18: {=IFERROR(IF(ROUNDUP((Client_Margin($C18)*Alloted(H$3,H$2,H$5)/Get_Margin(H$3,H$2,H$5,H$1)),0)*Get_Margin(H$3,H$2,H$5,H$1)>((Client_Margin($C18)*Alloted(H$3,H$2,H$5)/Get_Margin(H$3,H$2,H$5,H$1))*Get_Margin(H$3,H$2,H$5,H$1))*$D$3,ROUNDDOWN((Client_Margin($C18)*Alloted(H$3,H$2,H$5)/Get_Margin(H$3,H$2,H$5,H$1)),0),ROUNDUP((Client_Margin($C18)*Alloted(H$3,H$2,H$5)/Get_Margin(H$3,H$2,H$5,H$1)),0)),"-")} -> 8 | I18: {=IFERROR(IF(ROUNDUP((Client_Margin($C18)*Alloted(I$3,I$2,I$5)/Get_Margin(I$3,I$2,I$5,I$1)),0)*Get_Margin(I$3,I$2,I$5,I$1)>((Client_Margin($C18)*Alloted(I$3,I$2,I$5)/Get_Margin(I$3,I$2,I$5,I$1))*Get_Margin(I$3,I$2,I$5,I$1))*$D$3,ROUNDDOWN((Client_Margin($C18)*Alloted(I$3,I$2,I$5)/Get_Margin(I$3,I$2,I$5,I$1)),0),ROUNDUP((Client_Margin($C18)*Alloted(I$3,I$2,I$5)/Get_Margin(I$3,I$2,I$5,I$1)),0)),"-")} -> 3 | J18: {=IFERROR(IF(ROUNDUP((Client_Margin($C18)*Alloted(J$3,J$2,J$5)/Get_Margin(J$3,J$2,J$5,J$1)),0)*Get_Margin(J$3,J$2,J$5,J$1)>((Client_Margin($C18)*Alloted(J$3,J$2,J$5)/Get_Margin(J$3,J$2,J$5,J$1))*Get_Margin(J$3,J$2,J$5,J$1))*$D$3,ROUNDDOWN((Client_Margin($C18)*Alloted(J$3,J$2,J$5)/Get_Margin(J$3,J$2,J$5,J$1)),0),ROUNDUP((Client_Margin($C18)*Alloted(J$3,J$2,J$5)/Get_Margin(J$3,J$2,J$5,J$1)),0)),"-")} -> 3 | K18: {=IFERROR(IF(ROUNDUP((Client_Margin($C18)*Alloted(K$3,K$2,K$5)/Get_Margin(K$3,K$2,K$5,K$1)),0)*Get_Margin(K$3,K$2,K$5,K$1)>((Client_Margin($C18)*Alloted(K$3,K$2,K$5)/Get_Margin(K$3,K$2,K$5,K$1))*Get_Margin(K$3,K$2,K$5,K$1))*$D$3,ROUNDDOWN((Client_Margin($C18)*Alloted(K$3,K$2,K$5)/Get_Margin(K$3,K$2,K$5,K$1)),0),ROUNDUP((Client_Margin($C18)*Alloted(K$3,K$2,K$5)/Get_Margin(K$3,K$2,K$5,K$1)),0)),"-")} -> 0 | L18: {=IFERROR(IF(ROUNDUP((Client_Margin($C18)*Alloted(L$3,L$2,L$5)/Get_Margin(L$3,L$2,L$5,L$1)),0)*Get_Margin(L$3,L$2,L$5,L$1)>((Client_Margin($C18)*Alloted(L$3,L$2,L$5)/Get_Margin(L$3,L$2,L$5,L$1))*Get_Margin(L$3,L$2,L$5,L$1))*$D$3,ROUNDDOWN((Client_Margin($C18)*Alloted(L$3,L$2,L$5)/Get_Margin(L$3,L$2,L$5,L$1)),0),ROUNDUP((Client_Margin($C18)*Alloted(L$3,L$2,L$5)/Get_Margin(L$3,L$2,L$5,L$1)),0)),"-")} -> 0 | M18: {=IFERROR(IF(ROUNDUP((Client_Margin($C18)*Alloted(M$3,M$2,M$5)/Get_Margin(M$3,M$2,M$5,M$1)),0)*Get_Margin(M$3,M$2,M$5,M$1)>((Client_Margin($C18)*Alloted(M$3,M$2,M$5)/Get_Margin(M$3,M$2,M$5,M$1))*Get_Margin(M$3,M$2,M$5,M$1))*$D$3,ROUNDDOWN((Client_Margin($C18)*Alloted(M$3,M$2,M$5)/Get_Margin(M$3,M$2,M$5,M$1)),0),ROUNDUP((Client_Margin($C18)*Alloted(M$3,M$2,M$5)/Get_Margin(M$3,M$2,M$5,M$1)),0)),"-")} -> 0
A19: =_xlfn.XLOOKUP(C19,'OI QTY'!$O$5:$O$21,'OI QTY'!$N$5:$N$21,"") -> 0 | B19: =IF(C19="",0,1) -> 0 | E19: =SUM(F19:M19) -> 0.31341176 | F19: {=IFERROR((_xlfn._xlws.FILTER(INDEX(Margin[],0,MATCH(F$1&"_"&F$3,Margin[#Headers],0)),(Margin[Index]=F$2)*(Margin[Strategy]=F$5))*F18)/Client_Margin($C18),"-")} -> - | G19: {=IFERROR((_xlfn._xlws.FILTER(INDEX(Margin[],0,MATCH(G$1&"_"&G$3,Margin[#Headers],0)),(Margin[Index]=G$2)*(Margin[Strategy]=G$5))*G18)/Client_Margin($C18),"-")} -> - | H19: {=IFERROR((_xlfn._xlws.FILTER(INDEX(Margin[],0,MATCH(H$1&"_"&H$3,Margin[#Headers],0)),(Margin[Index]=H$2)*(Margin[Strategy]=H$5))*H18)/Client_Margin($C18),"-")} -> 0.10917647 | I19: {=IFERROR((_xlfn._xlws.FILTER(INDEX(Margin[],0,MATCH(I$1&"_"&I$3,Margin[#Headers],0)),(Margin[Index]=I$2)*(Margin[Strategy]=I$5))*I18)/Client_Margin($C18),"-")} -> 0.11011765 | J19: {=IFERROR((_xlfn._xlws.FILTER(INDEX(Margin[],0,MATCH(J$1&"_"&J$3,Margin[#Headers],0)),(Margin[Index]=J$2)*(Margin[Strategy]=J$5))*J18)/Client_Margin($C18),"-")} -> 0.094117647 | K19: {=IFERROR((_xlfn._xlws.FILTER(INDEX(Margin[],0,MATCH(K$1&"_"&K$3,Margin[#Headers],0)),(Margin[Index]=K$2)*(Margin[Strategy]=K$5))*K18)/Client_Margin($C18),"-")} -> 0 | L19: {=IFERROR((_xlfn._xlws.FILTER(INDEX(Margin[],0,MATCH(L$1&"_"&L$3,Margin[#Headers],0)),(Margin[Index]=L$2)*(Margin[Strategy]=L$5))*L18)/Client_Margin($C18),"-")} -> 0 | M19: {=IFERROR((_xlfn._xlws.FILTER(INDEX(Margin[],0,MATCH(M$1&"_"&M$3,Margin[#Headers],0)),(Margin[Index]=M$2)*(Margin[Strategy]=M$5))*M18)/Client_Margin($C18),"-")} -> 0
